<mujoco model="GEN3_MJCF">
  <compiler angle="radian" meshdir="meshes" autolimits="true"/>
  <option integrator="implicitfast"/>

  <default>
    <default class="GEN3_MJCF">
      <default class="visual">
        <!-- using stls for collision too -->
        <geom type="mesh" contype="0" conaffinity="0" group="2"/>
      </default>
      <default class="collision_capsule">
        <!-- template for your auto‑fitted primitives -->
        <geom type="capsule" group="3" contype="1" conaffinity="1"/>
      </default>
      <default class="collision_box">
        <geom type="box" group="3"/>
      </default>
    </default>
  </default>


  <asset>
    <material name="carbon" rgba="0.9 0.9 0.9 1"/>
    <!-- =========================
         Core robot‑arm link meshes
         ========================= -->
    <mesh name="base_link_mesh"
          file="c:\Users\arbxe\EmPRISE code\CRGP/Manip_planning/mp-osc/multipriority/urdfs/meshes/base_link.STL"/>
    <mesh name="shoulder_link_mesh"
          file="c:\Users\arbxe\EmPRISE code\CRGP/Manip_planning/mp-osc/multipriority/urdfs/meshes/shoulder_link.STL"/>
    <mesh name="half_arm_1_link_mesh"
          file="c:\Users\arbxe\EmPRISE code\CRGP/Manip_planning/mp-osc/multipriority/urdfs/meshes/half_arm_1_link.STL"/>
    <mesh name="half_arm_2_link_mesh"
          file="c:\Users\arbxe\EmPRISE code\CRGP/Manip_planning/mp-osc/multipriority/urdfs/meshes/half_arm_2_link.STL"/>
    <mesh name="forearm_link_mesh"
          file="c:\Users\arbxe\EmPRISE code\CRGP/Manip_planning/mp-osc/multipriority/urdfs/meshes/forearm_link.STL"/>
    <mesh name="spherical_wrist_1_mesh"
          file="c:\Users\arbxe\EmPRISE code\CRGP/Manip_planning/mp-osc/multipriority/urdfs/meshes/spherical_wrist_1_link.STL"/>
    <mesh name="spherical_wrist_2_mesh"
          file="c:\Users\arbxe\EmPRISE code\CRGP/Manip_planning/mp-osc/multipriority/urdfs/meshes/spherical_wrist_2_link.STL"/>
    <mesh name="bracelet_link_mesh"
          file="c:\Users\arbxe\EmPRISE code\CRGP/Manip_planning/mp-osc/multipriority/urdfs/meshes/bracelet_link.STL"/>

    <!-- =====================
         Tactile‑taxel meshes
         ===================== -->
    <mesh name="taxel_0_mesh"  file="taxel_0.STL"  scale="0.01 0.01 0.01"/>
    <mesh name="taxel_1_mesh"  file="taxel_1.STL"  scale="0.01 0.01 0.01"/>
    <mesh name="taxel_2_mesh"  file="taxel_2.STL"  scale="0.01 0.01 0.01"/>
    <mesh name="taxel_3_mesh"  file="taxel_3.STL"  scale="0.01 0.01 0.01"/>
    <mesh name="taxel_4_mesh"  file="taxel_4.STL"  scale="0.01 0.01 0.01"/>
    <mesh name="taxel_5_mesh"  file="taxel_5.STL"  scale="0.01 0.01 0.01"/>
    <mesh name="taxel_6_mesh"  file="taxel_6.STL"  scale="0.01 0.01 0.01"/>
    <mesh name="taxel_7_mesh"  file="taxel_7.STL"  scale="0.01 0.01 0.01"/>
    <mesh name="taxel_8_mesh"  file="taxel_8.STL"  scale="0.01 0.01 0.01"/>
    <mesh name="taxel_9_mesh"  file="taxel_9.STL"  scale="0.01 0.01 0.01"/>
    <mesh name="taxel_10_mesh" file="taxel_10.STL" scale="0.01 0.01 0.01"/>
    <mesh name="taxel_11_mesh" file="taxel_11.STL" scale="0.01 0.01 0.01"/>
    <mesh name="taxel_12_mesh" file="taxel_12.STL" scale="0.01 0.01 0.01"/>
    <mesh name="taxel_13_mesh" file="taxel_13.STL" scale="0.01 0.01 0.01"/>
    <mesh name="taxel_14_mesh" file="taxel_14.STL" scale="0.01 0.01 0.01"/>
    <mesh name="taxel_15_mesh" file="taxel_15.STL" scale="0.01 0.01 0.01"/>
    <mesh name="taxel_16_mesh" file="taxel_16.STL" scale="0.01 0.01 0.01"/>
    <mesh name="taxel_17_mesh" file="taxel_17.STL" scale="0.01 0.01 0.01"/>
    <mesh name="taxel_18_mesh" file="taxel_18.STL" scale="0.01 0.01 0.01"/>
    <mesh name="taxel_19_mesh" file="taxel_19.STL" scale="0.01 0.01 0.01"/>
    <mesh name="taxel_20_mesh" file="taxel_20.STL" scale="0.01 0.01 0.01"/>
    <mesh name="taxel_21_mesh" file="taxel_21.STL" scale="0.01 0.01 0.01"/>
    <mesh name="taxel_22_mesh" file="taxel_22.STL" scale="0.01 0.01 0.01"/>
    <mesh name="taxel_23_mesh" file="taxel_23.STL" scale="0.01 0.01 0.01"/>
    <mesh name="taxel_24_mesh" file="taxel_24.STL" scale="0.01 0.01 0.01"/>
    <mesh name="taxel_25_mesh" file="taxel_25.STL" scale="0.01 0.01 0.01"/>
    <mesh name="taxel_26_mesh" file="taxel_26.STL" scale="0.01 0.01 0.01"/>
    <mesh name="taxel_27_mesh" file="taxel_27.STL" scale="0.01 0.01 0.01"/>
  </asset>
  
  <worldbody>
    <body name="base_link">
      <site name="x" pos="0.2 0 0" size="0.05" rgba="1 0 0 1" type="sphere"/>
      <site name="y" pos="0 0.2 0" size="0.05" rgba="0 1 0 1" type="sphere"/>
      <site name="z" pos="0 0 0.2" size="0.05" rgba="0 0 1 1" type="sphere"/>
      <geom class="visual" mesh="base_link_mesh" pos="0 0 0" euler="0 0 0"/>
      <geom name="base_link_collision" class="collision_capsule" pos="-0.00358 -0.00007 0.08373" euler="0 0 0" size="0.05518 0.03060" group="3"/>
      <body name="Shoulder_Link" pos="0 0 0.15643" euler="3.1416 2.7629E-18 -4.9305E-36">
        <geom class="visual" mesh="shoulder_link_mesh" pos="0 0 0" euler="0 0 0"/>
        <geom name="shoulder_link_collision" class="collision_capsule" pos="0.00000 -0.01247 -0.08425" euler="0 0 0" size="0.036 0.06322" group="3"/>
        <joint name="Actuator1" type="hinge" axis="0 0 1"/>
        <body name="HalfArm1_Link" pos="0 0.005375 -0.12838" euler="1.5708 2.1343E-17 -1.1102E-16">
          <geom class="visual" mesh="half_arm_1_link_mesh" pos="0 0 0" euler="0 0 0"/>
          <geom name="half_arm_1_link_collision" class="collision_capsule" pos="0.00000 -0.09147 -0.01472" euler="1.45299 -0.00033 -0.00030" size="0.03648 0.09549" group="3"/>
          <joint name="Actuator2" type="hinge" axis="0 0 1"/>
          <body name="HalfArm2_Link" pos="0 -0.21038 -0.006375" euler="-1.5708 1.2326E-32 -2.9122E-16">
            <geom class="visual" mesh="half_arm_2_link_mesh" pos="0 0 0" euler="0 0 0"/>
            <geom name="half_arm_2_link_collision" class="collision_capsule" pos="-0.00001 -0.00837 -0.12799" euler="-0.07897 0.00216 -0.00009" size="0.03990 0.08905" group="3"/>
            <joint name="Actuator3" type="hinge" axis="0 0 1"/>
            <body name="ForeArm_Link" pos="0 0.006375 -0.21038" euler="1.5708 -6.6954E-17 -1.6653E-16">
              <geom class="visual" mesh="forearm_link_mesh" pos="0 0 0" euler="0 0 0"/>
              <geom name="forearm_link_collision" class="collision_capsule" pos="-0.00000 -0.08869 -0.01411" euler="1.45844 0.00078 0.00070" size="0.03382 0.09369" group="3"/>
              <joint name="Actuator4" type="hinge" axis="0 0 1"/>
              <body name="SphericalWrist1_Link" pos="0 -0.20843 -0.006375" euler="-1.5708 2.2204E-16 -6.373E-17">
                <geom class="visual" mesh="spherical_wrist_1_mesh" pos="0 0 0" euler="0 0 0"/>
                <geom name="spherical_wrist_1_link_collision" class="collision_capsule" pos="-0.00001 -0.01147 -0.06810" euler="-0.2 0.00280 -0.00042" size="0.03 0.04916" group="3"/>
                <joint name="Actuator5" type="hinge" axis="0 0 1"/>
                <body name="SphericalWrist2_Link" pos="0 0.00017505 -0.10593" euler="1.5708 9.2076E-28 -8.2157E-15">
                  <geom class="visual" mesh="spherical_wrist_2_mesh" pos="0 0 0" euler="0 0 0"/>
                  <geom name="spherical_wrist_2_link_collision" class="collision_capsule" pos="0.00000 -0.04532 -0.01004" euler="1.4 0.00506 0.00361" size="0.028 0.05413" group="3"/>
                  <joint name="Actuator6" type="hinge" axis="0 0 1"/>
                  <body name="Bracelet_Link" pos="0 -0.10593 -0.00017505" euler="-1.5708 -5.5511E-17 9.6396E-17">
                    <geom class="visual" mesh="bracelet_link_mesh" pos="0 0 0" euler="0 0 0"/>
                    <geom name="bracelet_link_collision" class="collision_capsule" pos="0 0 -0.02" euler="0 0 1.55" size="0.04 0.01350" group="3"/>
                    <geom name="bracelet_link_cam_collision" class="collision_capsule" pos="0 -0.06 -0.0525" euler="1.55 1.55 1.55" size="0.01 0.03" group="3"/>
                    <joint name="Actuator7" type="hinge" axis="0 0 1"/>
                    <site name="ee_site" pos="0 0 -0.061525" size="0.005" rgba="1 0 0 1" type="sphere"/>
                    <body name="EndEffector_Link" pos="0 0 -0.0615250000000001" euler="3.14159265358979 1.09937075168372E-32 0">
                    <body name="GraspPoint_Link" pos="0 0 0.15" euler="0 0 0"/>
                    </body>
                  </body>
                  <body name="Taxel_1000" pos="-0.04250419541867655 -0.07646850041798192 0.0007855905951708805" quat="-0.49549004670060454 -0.495757991613782 0.5555299010360846 -0.44732555977334937">
                    <geom class="visual" mesh="taxel_0_mesh" pos="0 0 0" euler="0 0 0"/>
                    <site name="Taxel_1000_contact_site" pos="0 0.02 0" size="0.003" rgba="0 1 0 1" type="sphere"/>
                  </body>
                  <body name="Taxel_1001" pos="-1.4938605298674768e-05 -0.040050790502569544 -0.051076626480111506" quat="0.617805545901906 0.500036500525442 0.3439452953116905 -0.4999814390835642">
                    <geom class="visual" mesh="taxel_1_mesh" pos="0 0 0" euler="0 0 0"/>
                    <site name="Taxel_1001_contact_site" pos="0.02 0 0" size="0.003" rgba="0 1 0 1" type="sphere"/>
                  </body>
                  <body name="Taxel_1002" pos="0.04271566985884755 -0.07873195857060433 -0.00022802633048775445" quat="0.4954036092387294 0.4958033669965902 0.5555786050791894 -0.44731051720963005">
                    <geom class="visual" mesh="taxel_2_mesh" pos="0 0 0" euler="0 0 0"/>
                    <site name="Taxel_1002_contact_site" pos="0 0.01 0" size="0.003" rgba="0 1 0 1" type="sphere"/>
                  </body>
                  <body name="Taxel_1003" pos="-1.241750836219415e-05 -0.07730975191366674 0.0431837840229755" quat="0.49999743644214245 -0.4721611775935851 -0.49998266763609944 -0.5263874219509945">
                    <geom class="visual" mesh="taxel_3_mesh" pos="0 0 0" euler="0 0 0"/>
                    <site name="Taxel_1003_contact_site" pos="0.02 0 0" size="0.003" rgba="0 1 0 1" type="sphere"/>
                  </body>
                </body>
             
                <body name="Taxel_1004" pos="0.043150247276728726 -0.0001254639437208889 -0.02783098306648868" quat="0.7066769085264963 -0.00022463346224831096 0.07598410627392084 -0.7034444626898383">
                  <geom class="visual" mesh="taxel_4_mesh" pos="0 0 0" euler="0 0 0"/>
                  <site name="Taxel_1004_contact_site" pos="0 0.01 0" size="0.003" rgba="0 1 0 1" type="sphere"/>
                </body>
                <body name="Taxel_1005" pos="-0.0002382337409993086 -0.05179760671765822 -0.06710984221647054" quat="-0.1153085765173002 -0.5917771330108392 -0.7931583735470257 0.0860438928644129">
                  <geom class="visual" mesh="taxel_5_mesh" pos="0 0 0" euler="0 0 0"/>
                  <site name="Taxel_1005_contact_site" pos="-0.02 0 0" size="0.003" rgba="0 1 0 1" type="sphere"/>
                </body>
                <body name="Taxel_1006" pos="-0.04318974980140639 -0.00010915210035311942 -0.02761946835919482" quat="-0.00020705373551838102 0.7066483360893822 -0.7034931457017315 0.07579894578119584">
                  <geom class="visual" mesh="taxel_6_mesh" pos="0 0 0" euler="0 0 0"/>
                  <site name="Taxel_1006_contact_site" pos="0 0.02 0" size="0.003" rgba="0 1 0 1" type="sphere"/>
                </body>
                <body name="Taxel_1007" pos="-1.1618120415300221e-05 0.043922698718644126 -0.02686054939608018" quat="-0.012048847971181305 -0.7191438184090834 -0.6946445765115851 0.012486233603918742">
                  <geom class="visual" mesh="taxel_7_mesh" pos="0 0 0" euler="0 0 0"/>
                  <site name="Taxel_1007_contact_site" pos="0.01 0 0" size="0.003" rgba="0 1 0 1" type="sphere"/>
                </body>
              </body>
             
              <body name="Taxel_1008" pos="0.047082560876994604 0.016625508860321547 -0.046140884202656954" quat="-0.4805499798966967 0.858991916812175 0.15563309194411742 -0.08356401357369031">
                <geom class="visual" mesh="taxel_8_mesh" pos="0 0 0" euler="0 0 0"/>
                <site name="Taxel_1008_contact_site" pos="0.02 0 0" size="0.003" rgba="0 1 0 1" type="sphere"/>
              </body>
              <body name="Taxel_1009" pos="-6.7198083501523495e-06 0.05300935180393007 -0.04461977697709482" quat="-0.5670672395281603 -0.42553302531393655 -0.4224050235932269 0.5647392196972744">
                <geom class="visual" mesh="taxel_9_mesh" pos="0 0 0" euler="0 0 0"/>
                <site name="Taxel_1009_contact_site" pos="0 0 -0.02" size="0.003" rgba="0 1 0 1" type="sphere"/>
              </body>
              <body name="Taxel_1010" pos="-0.047097438974916264 0.016627161287515402 -0.04613586787243025" quat="0.0602369798213798 0.2021183185586084 0.9406588744028733 0.2658581831957765">
                <geom class="visual" mesh="taxel_10_mesh" pos="0 0 0" euler="0 0 0"/>
                <site name="Taxel_1010_contact_site" pos="0.02 0 0" size="0.003" rgba="0 1 0 1" type="sphere"/>
              </body>
              <body name="Taxel_1011" pos="-7.590645030513553e-06 0.006405133918228834 -0.06439226342932816" quat="0.522767844447423 0.4999879804533483 0.4761357733791982 -0.5000205251012904">
                <geom class="visual" mesh="taxel_11_mesh" pos="0 0 0" euler="0 0 0"/>
                <site name="Taxel_1011_contact_site" pos="0.015 0 0" size="0.003" rgba="0 1 0 1" type="sphere"/>
              </body>
              <body name="Taxel_1012" pos="-8.828563007841432e-06 -0.08046080686920276 -0.059019306181966213" quat="-0.4520059513097711 0.4999844042629226 -0.5437829173089761 -0.5000063542769618">
                <geom class="visual" mesh="taxel_12_mesh" pos="0 0 0" euler="0 0 0"/>
                <site name="Taxel_1012_contact_site" pos="0.01 0 0" size="0.003" rgba="0 1 0 1" type="sphere"/>
              </body>
              <body name="Taxel_1013" pos="-9.803819467654521e-06 -0.16267771019312338 -0.050246400171184896" quat="-0.4729968354332207 0.49998467919878176 -0.5256263349749248 -0.5000062701781631">
                <geom class="visual" mesh="taxel_13_mesh" pos="0 0 0" euler="0 0 0"/>
                <site name="Taxel_1013_contact_site" pos="0.01 0 0" size="0.003" rgba="0 1 0 1" type="sphere"/>
              </body>
              <body name="Taxel_1014" pos="-0.04173526667542263 -0.15496948117011622 -0.005150262600599035" quat="0.46382658378034697 0.6036324755903242 0.48095446708854106 -0.43494314016768554">
                <geom class="visual" mesh="taxel_14_mesh" pos="0 0 0" euler="0 0 0"/>
                <site name="Taxel_1014_contact_site" pos="0 -0.02 0" size="0.003" rgba="0 1 0 1" type="sphere"/>
              </body>
              <body name="Taxel_1015" pos="0.04171973319335233 -0.15497094542273304 -0.005154707682772205" quat="0.6036291485234604 0.46382756270924497 0.4349297022427556 -0.4809698506466614">
                <geom class="visual" mesh="taxel_15_mesh" pos="0 0 0" euler="0 0 0"/>
                <site name="Taxel_1015_contact_site" pos="0 0.02 0" size="0.003" rgba="0 1 0 1" type="sphere"/>
              </body>
              <body name="Taxel_1016" pos="-5.302853516851408e-06 -0.15282581480448965 0.031012491151505076" quat="0.6462897966083897 0.5000072377234106 -0.28691403824118467 0.4999825953813064">
                <geom class="visual" mesh="taxel_16_mesh" pos="0 0 0" euler="0 0 0"/>
                <site name="Taxel_1016_contact_site" pos="0.01 0 0" size="0.003" rgba="0 1 0 1" type="sphere"/>
              </body>
              <body name="Taxel_1017" pos="-6.150508083981775e-06 -0.07701626534250128 -0.00987434420722404" quat="0.6315248277215402 0.5000070455175422 -0.31809817569846033 0.4999828967288872">
                <geom class="visual" mesh="taxel_17_mesh" pos="0 0 0" euler="0 0 0"/>
                <site name="Taxel_1017_contact_site" pos="0.01 0 0" size="0.003" rgba="0 1 0 1" type="sphere"/>
              </body>
            </body>
             
            <body name="Taxel_1018" pos="0.04775940299230756 -0.029172408330763868 -0.2301544199406168" quat="0.10118046495791487 -0.6607838065674745 -0.6510725478148105 0.35948826402405704">
              <geom class="visual" mesh="taxel_18_mesh" pos="0 0 0" euler="0 0 0"/>
              <site name="Taxel_1018_contact_site" pos="0 0.01 0" size="0.003" rgba="0 1 0 1" type="sphere"/>
            </body>
            <body name="Taxel_1019" pos="-2.092488763690554e-06 -0.02694220419582137 -0.2644489118296661" quat="-0.5336432730072895 0.46391741331801667 -0.5336525415671008 -0.4639185873333399">
              <geom class="visual" mesh="taxel_19_mesh" pos="0 0 0" euler="0 0 0"/>
              <site name="Taxel_1019_contact_site" pos="0.02 0 0" size="0.003" rgba="0 1 0 1" type="sphere"/>
            </body>
            <body name="Taxel_1020" pos="-0.04713575005582718 -0.026383465676048472 -0.23055139832768035" quat="0.18126608498340646 0.035504008467736076 0.9677098631757791 0.17152169696521297">
              <geom class="visual" mesh="taxel_20_mesh" pos="0 0 0" euler="0 0 0"/>
              <site name="Taxel_1020_contact_site" pos="0.02 0 0" size="0.003" rgba="0 1 0 1" type="sphere"/>
            </body>
            <body name="Taxel_1021" pos="-1.2173507245044695e-06 -0.054580934607185494 -0.22775170878253925" quat="-0.05055865348607764 -0.6565271540612538 -0.7513077310057058 0.04418836802783569">
              <geom class="visual" mesh="taxel_21_mesh" pos="0 0 0" euler="0 0 0"/>
              <site name="Taxel_1021_contact_site" pos="-0.02 0 0" size="0.003" rgba="0 1 0 1" type="sphere"/>
            </body>
            <body name="Taxel_1022" pos="-0.0001333060986898991 -0.05338028930573722 -0.1389517161450241" quat="0.020944198492622863 0.6861879570978644 -0.7268540200870826 0.01976516042454964">
              <geom class="visual" mesh="taxel_22_mesh" pos="0 0 0" euler="0 0 0"/>
              <site name="Taxel_1022_contact_site" pos="0.02 0 0" size="0.003" rgba="0 1 0 1" type="sphere"/>
            </body>
            <body name="Taxel_1023" pos="-3.23855682768594e-05 -0.05187961469696644 -0.04785172827035311" quat="0.012129581476701687 0.7192487626159917 -0.6945333033911236 0.012553135432175103">
              <geom class="visual" mesh="taxel_23_mesh" pos="0 0 0" euler="0 0 0"/>
              <site name="Taxel_1023_contact_site" pos="0.02 0 0" size="0.003" rgba="0 1 0 1" type="sphere"/>
            </body>
            <body name="Taxel_1024" pos="-0.0500349226337144 -0.007382389594276225 -0.06305150607070498" quat="-0.08616818804246879 0.7071257885121112 -0.7018177559578025 -3.599643069895908e-06">
              <geom class="visual" mesh="taxel_24_mesh" pos="0 0 0" euler="0 0 0"/>
              <site name="Taxel_1024_contact_site" pos="0.01 0 0" size="0.003" rgba="0 1 0 1" type="sphere"/>
            </body>
            <body name="Taxel_1025" pos="0.05086506074464583 -0.00737702635118296 -0.06455261415550584" quat="-0.09841668563118262 -0.70712506759444 0.7002058945533199 -1.310240171914501e-06">
              <geom class="visual" mesh="taxel_25_mesh" pos="0 0 0" euler="0 0 0"/>
              <site name="Taxel_1025_contact_site" pos="0.01 0 0" size="0.003" rgba="0 1 0 1" type="sphere"/>
            </body>
            <body name="Taxel_1026" pos="0.0018625242094073681 0.04412050179254166 -0.0457524543636606" quat="0.6940955158731572 -0.13492466600078207 0.13492510223719884 0.6941339684352255">
              <geom class="visual" mesh="taxel_26_mesh" pos="0 0 0" euler="0 0 0"/>
              <site name="Taxel_1026_contact_site" pos="0.01 0 0" size="0.003" rgba="0 1 0 1" type="sphere"/>
            </body>
            <body name="Taxel_1027" pos="0.0008638901480674864 0.004619954887956686 -0.11295215320413332" quat="0.687549540441228 -0.16507394606822146 0.1650727046122378 0.6875879754333428">
              <geom class="visual" mesh="taxel_27_mesh" pos="0 0 0" euler="0 0 0"/>
              <site name="Taxel_1027_contact_site" pos="0.01 0 0" size="0.003" rgba="0 1 0 1" type="sphere"/>
            </body>
        
          </body>
        </body>
      </body>
    </body>
  </worldbody>
  <actuator>
    <position name="act1" joint="Actuator1" kp="2000" kv="100"
              ctrlrange="-3.142 3.142" forcerange="-39 39"/>
    <position name="act2" joint="Actuator2" kp="2000" kv="100"
              ctrlrange="-2.41 2.41"   forcerange="-39 39"/>
    <position name="act3" joint="Actuator3" kp="2000" kv="100"
              ctrlrange="-3.142 3.142" forcerange="-39 39"/>
    <position name="act4" joint="Actuator4" kp="2000" kv="100"
              ctrlrange="-2.66 2.66"   forcerange="-39 39"/>
    <position name="act5" joint="Actuator5" kp="500"  kv="25"
              ctrlrange="-3.142 3.142" forcerange="-9 9"/>
    <position name="act6" joint="Actuator6" kp="500"  kv="25"
              ctrlrange="-2.23 2.23"   forcerange="-9 9"/>
    <position name="act7" joint="Actuator7" kp="500"  kv="25"
              ctrlrange="-3.142 3.142" forcerange="-9 9"/>
  </actuator>
</mujoco>